2024-03-20T16:45:02,349 Checking in d:\tts for .bzr (bzr)...
2024-03-20T16:45:02,350 Checking in d:\tts for .git (git)...
2024-03-20T16:45:02,350 Running command git rev-parse --show-toplevel
2024-03-20T16:45:02,351 ERROR: Exception:
2024-03-20T16:45:02,351 Traceback (most recent call last):
2024-03-20T16:45:02,351   File "C:\Users\USER\AppData\Local\Programs\Python\Python311\Lib\site-packages\pip\_internal\cli\base_command.py", line 180, in exc_logging_wrapper
2024-03-20T16:45:02,351     status = run_func(*args)
2024-03-20T16:45:02,351              ^^^^^^^^^^^^^^^
2024-03-20T16:45:02,351   File "C:\Users\USER\AppData\Local\Programs\Python\Python311\Lib\site-packages\pip\_internal\commands\freeze.py", line 98, in run
2024-03-20T16:45:02,351     for line in freeze(
2024-03-20T16:45:02,351   File "C:\Users\USER\AppData\Local\Programs\Python\Python311\Lib\site-packages\pip\_internal\operations\freeze.py", line 43, in freeze
2024-03-20T16:45:02,351     req = FrozenRequirement.from_dist(dist)
2024-03-20T16:45:02,351           ^^^^^^^^^^^^^^^^^^^^^^^^^^^^^^^^^
2024-03-20T16:45:02,351   File "C:\Users\USER\AppData\Local\Programs\Python\Python311\Lib\site-packages\pip\_internal\operations\freeze.py", line 238, in from_dist
2024-03-20T16:45:02,351     req, comments = _get_editable_info(dist)
2024-03-20T16:45:02,351                     ^^^^^^^^^^^^^^^^^^^^^^^^
2024-03-20T16:45:02,351   File "C:\Users\USER\AppData\Local\Programs\Python\Python311\Lib\site-packages\pip\_internal\operations\freeze.py", line 165, in _get_editable_info
2024-03-20T16:45:02,351     vcs_backend = vcs.get_backend_for_dir(location)
2024-03-20T16:45:02,351                   ^^^^^^^^^^^^^^^^^^^^^^^^^^^^^^^^^
2024-03-20T16:45:02,351   File "C:\Users\USER\AppData\Local\Programs\Python\Python311\Lib\site-packages\pip\_internal\vcs\versioncontrol.py", line 238, in get_backend_for_dir
2024-03-20T16:45:02,351     repo_path = vcs_backend.get_repository_root(location)
2024-03-20T16:45:02,351                 ^^^^^^^^^^^^^^^^^^^^^^^^^^^^^^^^^^^^^^^^^
2024-03-20T16:45:02,351   File "C:\Users\USER\AppData\Local\Programs\Python\Python311\Lib\site-packages\pip\_internal\vcs\git.py", line 501, in get_repository_root
2024-03-20T16:45:02,351     r = cls.run_command(
2024-03-20T16:45:02,351         ^^^^^^^^^^^^^^^^
2024-03-20T16:45:02,351   File "C:\Users\USER\AppData\Local\Programs\Python\Python311\Lib\site-packages\pip\_internal\vcs\versioncontrol.py", line 650, in run_command
2024-03-20T16:45:02,351     return call_subprocess(
2024-03-20T16:45:02,351            ^^^^^^^^^^^^^^^^
2024-03-20T16:45:02,351   File "C:\Users\USER\AppData\Local\Programs\Python\Python311\Lib\site-packages\pip\_internal\utils\subprocess.py", line 141, in call_subprocess
2024-03-20T16:45:02,351     proc = subprocess.Popen(
2024-03-20T16:45:02,351            ^^^^^^^^^^^^^^^^^
2024-03-20T16:45:02,351   File "C:\Users\USER\AppData\Local\Programs\Python\Python311\Lib\subprocess.py", line 1026, in __init__
2024-03-20T16:45:02,351     self._execute_child(args, executable, preexec_fn, close_fds,
2024-03-20T16:45:02,351   File "C:\Users\USER\AppData\Local\Programs\Python\Python311\Lib\subprocess.py", line 1538, in _execute_child
2024-03-20T16:45:02,351     hp, ht, pid, tid = _winapi.CreateProcess(executable, args,
2024-03-20T16:45:02,351                        ^^^^^^^^^^^^^^^^^^^^^^^^^^^^^^^^^^^^^^^
2024-03-20T16:45:02,351 NotADirectoryError: [WinError 267] The directory name is invalid
